Workbook
Name afa_visszaig: Háttér_listák!$B$129:$B$130
Name áll_tám_i: Háttér_listák!$B$84
Name áll_tám_n: Háttér_listák!$B$85
Name áll_tám_rel: Főoldal!$F$20
Name azon_valaszt: Háttér_listák!$B$9
Name edr: Főoldal!$D$90
Name elozo_valasz: Háttér_listák!$B$77
Name elsz_nem_elsz_ktg: Háttér_listák!$B$125:$B$126
Name eur: Főoldal!$D$79
Name fdr_áll: Főoldal!$D$88
Name fdr_nem_áll: Főoldal!$D$89
Name Felh_azon: Háttér_listák!$B$89:$B$117
Name Felh_cím: Háttér_listák!$C$89:$C$117
Name felh_valaszt: Háttér_listák!$B$42:$B$43
Name felh_valaszt_list: Háttér_listák!$B$47:$B$75
Name gazd_tev: Főoldal!$E$20
Name i_n_list: Háttér_listák!$B$3:$B$5
Name ker_hat: Főoldal!$E$22
Name kiv_tam_jogcim: Főoldal!$C$59:$C$76
Name korny_kar_list: Háttér_listák!$B$178:$B$181
Name köv_valaszoljon: Háttér_listák!$B$78
Name közc_tev: Főoldal!$E$24
Name ktg_sor: Háttér_listák!$B$121:$B$122
Name last_year: Főoldal!$D$86
Name megujulo_energia: Háttér_listák!$B$172:$B$173
Name muk_tam_cs: Működési_input!$C$58
Name ne_valaszoljon: Háttér_listák!$B$79
Name nem_áll_tám: Háttér_listák!#REF!
Name nem_rel: Háttér_listák!$B$143
Name null_data: Háttér_listák!#REF!
Name oke: Háttér_listák!$B$82
Name op_start: Főoldal!$D$83
Name penz_fennt__i: Háttér_listák!$C$146
Name penz_fennt_n: Háttér_listák!$C$147
Name pü_bev_nem_áll: Működési_input!$D$11:$AG$11
Name pü_egyéb_pá_nem_áll: Működési_input!$D$13:$AG$13
Name pü_OM_nem_áll: Működési_input!$D$27:$AG$27
Name pü_önerő_nem_áll: Működési_input!$D$48:$AG$52
Name pü_pótl_nem_áll: Működési_input!$D$28:$AG$28
Name reg_tam_arany_onkorm: Háttér_listák!$D$19:$D$38
Name start_year: Főoldal!$D$81
Name Szerv_form: Háttér_listák!$B$13:$B$16
Name Tam_jogcim: Háttér_listák!$B$155:$B$167
Name torolje: Háttér_listák!$B$80
Name valaszoljon: Háttér_listák!$B$81
Name Varmegye: Háttér_listák!$B$19:$B$38

Sheet Háttér_listák
B2: i_n_list
B3: igen
B4: nem
B8: azon_valaszt
B9: Kérjük válassza ki a pályázati felhívás azonosítóját!
B12: Szerv_form
B13: önkormányzat
B14: kisvállalkozás
B15: középvállalkozás
B16: nagyvállalkozás
B18: Varmegye | D18: önkormányzat | E18: kisvállalkozás | F18: középvállalkozás | G18: nagyvállalkozás
B19: Borsod-Abaúj-Zemplén vármegye | C19: Észak-Magyarország | D19: 0.6 | E19: 0.8 | F19: 0.7 | G19: 0.6
B20: Heves vármegye | C20: Észak-Magyarország | D20: 0.6 | E20: 0.8 | F20: 0.7 | G20: 0.6
B21: Nógrád vármegye | C21: Észak-Magyarország | D21: 0.5 | E21: 0.7 | F21: 0.6 | G21: 0.5
B22: Hajdú-Bihar vármegye | C22: Észak-Alföld | D22: 0.5 | E22: 0.7 | F22: 0.6 | G22: 0.5
B23: Jász-Nagykun-Szolnok vármegye | C23: Észak-Alföld | D23: 0.5 | E23: 0.7 | F23: 0.6 | G23: 0.5
B24: Szabolcs-Szatmár-Bereg vármegye | C24: Észak-Alföld | D24: 0.5 | E24: 0.7 | F24: 0.6 | G24: 0.5
B25: Bács-Kiskun vármegye | C25: Dél-Alföld | D25: 0.5 | E25: 0.7 | F25: 0.6 | G25: 0.5
B26: Békés vármegye | C26: Dél-Alföld | D26: 0.5 | E26: 0.7 | F26: 0.6 | G26: 0.5
B27: Csongrád-Csanád vármegye | C27: Dél-Alföld | D27: 0.5 | E27: 0.7 | F27: 0.6 | G27: 0.5
B28: Pest vármegye | C28: Pest | D28: 0.5 | E28: 0.7 | F28: 0.6 | G28: 0.5
B29: Budapest | C29: Budapest | D29: 0 | E29: 0.2 | F29: 0.1 | G29: 0
B30: Fejér vármegye | C30: Közép-Dunántúl | D30: 0.3 | E30: 0.5 | F30: 0.4 | G30: 0.3
... B38: Tolna vármegye | C38: Dél-Dunántúl | D38: 0.5 | E38: 0.7 | F38: 0.6 | G38: 0.5
B41: felh_valaszt
B42: felhívás azonosítója alapján | C42: 1
B43: felhívás címe alapján | C43: 2
B44: =INDEX($C$42:$C$43,MATCH(Főoldal!$C$11,felh_valaszt,0)) -> 1
B46: felh_valaszt_list | D46: Állami támogatási relevancia 1= lehet áll. Tám. 0= nem lehet áll. Tám.
B47: {=IFERROR(IF($B$44=C42,Felh_azon,Felh_cím),"")} -> TOP_PLUSZ-1.3.2-23 | C47: {=IFERROR(IF($B$44=$C$42,Felh_cím,Felh_azon),"")} -> Fenntartható városfejlesztés | D47: 1
B48: TOP_PLUSZ-2.1.2-21 | C48: Fenntartható energiahatékonyság | D48: 1
B49: TOP_PLUSZ-3.1.3-23 | C49: Helyi humán fejlesztések | D49: 0
B50: TOP_PLUSZ-3.2.1-23 | C50: Fenntartható humán fejlesztések | D50: 0
B51: TOP_PLUSZ-3.3.3-23 | C51: Köznevelési infrastruktúra fejlesztése | D51: 0
B52: TOP_PLUSZ-3.4.1-23 | C52: Fenntartható humán infrastruktúra | D52: 0
B53: TOP_PLUSZ-4.1.2-23 | C53: BRINGASZTRÁDA PROGRAM | D53: 1
B54: TOP_PLUSZ-4.1.3-23 | C54: Komplex klímaadaptációs és közterület-megújítási program | D54: 1
B55: TOP_PLUSZ-6.1.4-23 | C55: Aktív turizmus fejlesztése | D55: 1
B56: TOP_PLUSZ-6.2.1-23 | C56: Fenntartható versenyképes városfejlesztés | D56: 1
B57: TOP_Plusz-4.2.2-25 | C57: Az energiaszegénység enyhítése szilárd tüzelésű háztartások átállításával fővárosi pilot projekt keretében | D57: 1
...

Sheet Ábra
H3: Gazdasági tevékenységet végez?
H5: Nem | L5: Igen
N7: Kereskedelemre hatással van?
L9: Nem | N9: Igen
N11: Folytat nem állami támogatás alá eső tevékenységet is?
J13: Igen | N13: Nem
H15: Nem állami támogatás a projekt vagy része | N15: Állami támogatás a projekt vagy része
H18: Nettó működési bevétel keletkezik? | N18: Nettó működési bevételt figyelembe veszi a támogatási szabály?
F20: Nem | H20: Igen | L20: Nem | P20: Igen
H22: A közcélra vonatkozó működési támogatás mértékét csökkenti a nettó bevétel összegével? | P22: Nettó működési bevétel keletkezik?
H24: Igen | J24: Nem | N24: Nem | P24: Igen
F26: PF szerinti maximális támogatási arány | H26: PF szerinti maximális támogatási arány | J26: Finanszírozási hiány ráta számítás | L26: PF, illetve támogatási szabály szerinti maximális támogatási arány | N26: PF, illetve támogatási szabály szerinti maximális támogatási arány | P26: Nettó működési bevétel levonásával, releváns szabály szerint
D33: A megfelelő támogatási szabályt számoló munkalapra mutató hivatkozás | F33: nem_áll_egyszerű!A1 | H33: nem_áll_egyszerű!A1 | J33: nem_áll_fin_hiány!A1 | L33: áll_tám_egyszerű!A1 | N33: áll_tám_egyszerű!A1 | P33: áll_tám_műk_eredmény!A1
H38: Nem állami támogatás a projekt vagy része | N38: Állami támogatás a projekt vagy része
F40: Nem állami támogatás, nettó működési bevétel nem keletkezik | H40: Nem állami támogatás, nettó működési bevétel keletkezik, amivel csökkentik a működési támogatást | J40: Nem állami támogatás, nettó működési bevétel keletkezik, amivel nem csökkentik a működési támogatást | L40: Állami támogatás, nettó működési bevételt nem veszi figyelembe a támogatási szabály | N40: Állami támogatás, nettó működési bevételt figyelembe veszi a támogatási szabály, nettó működési bevétel nem keletkezik | P40: Állami támogatás, nettó működési bevételt figyelembe veszi a támogatási szabály, nettó működési bevétel keletkezik
F42: PF szerinti maximális támogatási arány | H42: PF szerinti maximális támogatási arány | J42: Finanszírozási hiány ráta számítás | L42: PF, illetve támogatási szabály szerinti maximális támogatási arány | N42: PF, illetve támogatási szabály szerinti maximális támogatási arány | P42: Nettó működési bevétel levonásával, releváns szabály szerint
D44: Támogatás szükségességének alátámasztása | F44: Nem szükséges | H44: Nem szükséges | J44: Igen, finanszírozási hiány ráta számítással | L44: A támogatási arány számításának módjától függ | N44: A támogatási arány számításának módjától függ | P44: Szükséges
D46: Pénzügyi teljesítménymutatók meghatározása | F46: Nem szükséges | H46: Pénzáramok becslése szükséges | J46: Szükséges | L46: Szükséges, egyszerűsített pénzáramok alapján | N46: Szükséges, egyszerűsített pénzáramok alapján | P46: Szükséges
D48: Pénzügyi fenntarthatóság alátámasztása | F48: Szükséges, pénzáramok becslése nagyvonalú | H48: Szükséges, pénzáramok becslése nagyvonalú | J48: Szükséges, részletes | L48: Szükséges, pénzáramok becslése nagyvonalú | N48: Szükséges, pénzáramok becslése nagyvonalú | P48: Szükséges, részletes

Sheet Főoldal
B2: Kitöltési útmutató | C2: A kitöltés során kizárólag a kék háttérrel jelölt cellákba szükséges adatokat megadni, a zöld betűszínű cellák magyarázatként szolgálnak. Ezek a mezők tartalmazzák a felhasználó által megadandó inputokat. Amennyiben egy ilyen cella mellett „Ellenőrzés” vagy egyéb megjegyzés szerepel, az ott található kiegészítő információt minden esetben el kell olvasni és figyelembe kell venni a kitöltés során, mivel az értelmezést, érvényességet vagy követelményeket pontosítja. Az adatokat minden esetben az adott felhívás tartalmi és formai követelményeinek megfelelően, a konkrét projekt sajátosságait figyelembe véve kell megadni. Az információk kitöltése során különösen fontos a koherencia és az adatok konzisztenciája a projekt más dokumentumaival. A beruházási és működési költségek megadására külön munkalapok szolgálnak, ezek egymástól elkülönítetten, de egységes logika mentén kerültek kialakításra. Ezeken a lapokon szükséges részletezni minden olyan költségelemet, amely a projekt pénzügyi elemzése szempontjából releváns.A számításokat a Háttér munkalapon lehet részletezni. A támogatás számításának módszertanát az „Ábra” elnevezésű munkalap szemlélteti. Ennek alapján kerültek kialakításra minta munkalapok, melyek közül a megfelelő lap(ok) kitöltése kötelező a pénzügyi számítások végrehajtásához. Ez biztosítja, hogy az alkalmazott logika átlátható és a számítási mód ellenőrizhető legyen. Amennyiben a projekt több támogatási jogcímet is érint, minden egyes releváns jogcím esetében külön-külön el kell végezni a vonatkozó pénzügyi számításokat. A beruházási költségek támogatási jogcímekre történő szétosztásakor a járulékos költségeket arányosan szét kell osztani az egyes projektelemekre. Ilyen esetben a „Pénzügyi elemzés” munkalapon ezen részszámítások összesítésével egy konszolidált, a teljes projektre vonatkozó elemzést is szükséges elkészíteni. A közgazdasági elemzést - amennyiben szükséges - minden esetben projekt szinten kell elvégezni. Ennek során a kapcsolódó munkalapon a szükséges bemeneti adatokat kell megadni, amelyek alapján a társadalmi hasznosság és gazdasági indokoltság értékelhetővé válik. Végezetül, a munkafüzet tartalmaz egy külön munkalapot, amely az érzékenységvizsgálat, a küszöbérték-számítás, valamint a forgatókönyv-elemzés kereteit mutatja be. Minden esetben a releváns háttérszámításokat az erre kijelölt üres munkalapon kell bemutatni, hogy a megadott adatok ellenőrizhetők, nyomonkövethetők legyenek.
F3: Ellenőrzés
B4: A projekt címe | C4: Teszt | F4: =IF(C4="",valaszoljon,"")
B6: Pályázó neve | C6: Teszt Város | F6: =IF(C6="",valaszoljon,"")
B8: Pályázó szervezeti formája (önkormányzat, kisvállalkozás, középvállalkozás, nagyvállalkozás) | C8: kisvállalkozás | F8: =IF(C8="",valaszoljon,"")
B9: Pályázó székhelye vármegye szerint | C9: Komárom-Esztergom vármegye | F9: =IF(C9="",valaszoljon,"")
B11: Felhívás kiválasztása | C11: felhívás azonosítója alapján | F11: =IF(C11="",valaszoljon,"")
B13: =IF($C$11=Háttér_listák!$B$42,"Felhívás azonosítója","Felhívás címe") -> Felhívás azonosítója | C13: TOP_PLUSZ-1.3.2-23
B14: =IF($C$11=Háttér_listák!$B$42,"Felhívás címe","Felhívás azonosítója") -> Felhívás címe | C14: =IFERROR(INDEX(_xlfn.ANCHORARRAY(Háttér_listák!$C$47),MATCH(Főoldal!$C$13,felh_valaszt_list,0)),"HIBÁS KITÖLTÉS") -> Fenntartható városfejlesztés
B15: Az elszámolható költségek nem visszaigényelhető áfa-tartalma a projekt kiírás alapján elszámolható költség, vagy nem? | C15: igen
C17: =IFERROR(IF(C13="","",IF(INDEX(Háttér_listák!$D$47:$D$75,MATCH(Főoldal!$C$13,felh_valaszt_list,0))=1,köv_valaszoljon,ne_valaszoljon)),"") -> Kérjük válaszoljon a következő kérdésekre!
B19: Kérdés | C19: Magyarázat | D19: Értékelés | E19: Válasz | F19: Ellenőrzés | G19: Szöveges indoklás
B20: 1. A kedvezményezett (az épület üzemeltetője/ fenntartója/ tulajdonosa) gazdasági tevékenységet végez-e, azaz vállalkozásnak minősül-e? A projekt keretében megtermelt energia harmadik fél részére történő értékesítése is gazdasági tevékenységnek minősül! | C20: Kérjük válasszon a legördülő listában felkínált válaszok (igen/ nem) közül az alábbi útmutatás alapján. Kérjük válaszát indokolja! Gazdasági és a nem gazdasági tevékenységek közötti különbségtétel: Az Európai Bíróság következetes ítélkezési gyakorlata szerint - bármely tevékenység, amelynek keretében valamely piacon árukat és szolgáltatásokat kínálnak, gazdasági tevékenységnek minősül. Az a jogalany, amely egyszerre végez gazdasági és nem gazdasági tevékenységet, csak az előbbi tekintetében minősül vállalkozásnak. Az alábbi szolgáltatások jellemzően nem gazdasági tevékenységek, azonban gazdasági tevékenységnek is minősülhetnek. Mivel ezekben az esetekben nehezebb a különbségtétel, ezért a Bizottsági közlemény az Európai Unió működéséről szóló szerződés 107. cikkének (1) bekezdésében említett állami támogatás fogalmáról C/2016/2946 útmutatást ad a besorolásra. Ennek kivonatát tartalmazza az alábbi kimutatás, részletesebb elemzésért kérjük tanulmányozza a Bizottsági közleményt! Közhatalom gyakorlása, pl. rendőrség, polgárőrség, közterületfelügyelet: amennyiben egy közjogi jogalany olyan gazdasági tevékenységet folytat, amelyet el lehet választani a közhatalmi jogosítványainak gyakorlásától, e jogalany az említett tevékenységgel kapcsolatban vállalkozásként jár el. Szociális biztonság, pl. szociális intézmények, bölcsőde: jellemzően nem tekinthető gazdasági tevékenységnek, amennyiben a szolidaritás elvére épül. Ha ennek a rendszernek a jellemzői érvényesülnek jellemzően, akkor nem gazdasági tevékenység: • kötelező a tagság, kizárólag szociális célokat követ, nonprofit alapon működik, az ellátások függetlenek a befizetett járulékoktól, az ellátások nem szükségszerűen arányosak a biztosított személy bevételeivel, a rendszert az állam/ önkormányzat felügyeli. A gazdasági tevékenység végzésének jellemző elemei: • választható tagság, tőkefedezeti elv, nyereségszerzésre törekvés, kiegészítő jogosultságok nyújtása. Néhány rendszer mindkét kategória egyes jellemzőit magában foglalja. Ilyen esetekben elemezni kell a különböző elemeket és azok jelentőségét. Egészségügyi ellátás, pl. kórház, szakrendelő: ha majdnem teljes egészében a szolidaritás elvére épül (társadalombiztosítási járulékból vagy egyéb állami forrásból finanszírozzák, szolgáltatásaikat a rendszer minden tagja számára térítésmentesen biztosítják), nem minősül vállalkozásnak. Amennyiben az egészségügyi szolgáltató a szolgáltatásait díjazás ellenében nyújtja, amelyet közvetlenül a beteg vagy annak biztosítója fizet, akkor gazdasági tevékenységnek minősül. Oktatási és kutatási tevékenység, óvodák, magán és állami iskolák, szakképzés, egyetemi oktatás: az állam által finanszírozott és felügyelt nemzeti oktatási rendszer keretében megszervezett közoktatás nem gazdasági tevékenység. A befizetett hozzájárulások (beiratkozási díj, esetleg tandíj) a szolgáltatás valódi költségének csupán töredékét fedezi. Gazdasági tevékenységnek minősül az az oktatási tevékenység, amelyet elsősorban a szülők vagy tanulók befizetéseiből, vagy üzleti bevételekből finanszíroznak. Kultúra, kulturális örökség megőrzése, természetvédelem, pl. múzeumok, levéltárak, könyvtárak, művészeti és kulturális központok vagy terek, színházak, operaházak, koncerttermek, régészeti lelőhelyek, műemlékek, történelmi helyszínek és épületek, hagyományok és mesterségek, fesztiválok és kiállítások, valamint kulturális és művészeti oktatási tevékenységek, természeti örökség (biológiai sokféleség, természetes élőhelyek, fajok megőrzése) védelme: A nagyközönség számára térítésmentesen, vagy a valódi költségek csupán töredését fedező pénzügyi hozzájárulás ellenében hozzáférhető tevékenység nem gazdasági jellegű. Ezzel ellentétben az elsősorban látogatók által vagy belépődíjakból vagy más kereskedelmi eszközökkel finanszírozott tevékenységeket gazdasági jellegűnek kell minősíteni. Ehhez hasonlóan az olyan tevékenységeket, amelyek kizárólag bizonyos vállalkozásokat juttatnak előnyhöz rendszerint gazdasági jellegűnek kell minősíteni. A Felhívás keretében támogatható tevékenységek finanszírozása a támogatást igénylő szintjén abban az esetben nem minősül az EUMSZ 107. cikk (1) bekezdése szerinti állami támogatásnak,amennyiben a támogatott tevékenység nem gazdasági tevékenységre használt infrastruktúra ún. szokásos létesítményeihez kapcsolódik (ilyen szokásos létesítmény például egy múzeum büféje, ha a múzeum tevékenysége nem minősül gazdasági tevékenységnek). Olyan esetekben, amelyekben egy jogalany kulturális vagy a kulturális örökség megőrzéséhez kapcsolódó olyan tevékenységeket végez, amelyek némelyike nem gazdasági tevékenység, némelyike pedig gazdasági tevékenység, a jogalany által kapott állami finanszírozás csak annyiban tartozik az állami támogatási szabályok hatálya alá, amennyiben az a gazdasági tevékenységekhez kapcsolódó költségeket fedezi. Az épületenergetikai felhívás szempontjából releváns lehet, hogy a projekt keretében megtermelt energia harmadik fél részére értékesítésre kerül. Amennyiben ez így lesz, a termelt energia értékesítése lesz maga a gazdasági tevékenység. Az elnyert projekt keretében megtermelt villamos energia hálózatra történő csatlakozása és a bruttó elszámolás alkalmazása nem minősül gazdasági tevékenységnek. | D20: Amennyiben tevékenysége jellemzően nem gazdasági tevékenységnek minősül, a "nem" válasz elfogadható. Ebben az esetben a támogatás nem minősül állami támogatásnak. Amennyiben részben vagy egészben gazdasági tevékenységnek minősül, az "igen" választ kell megadni. | E20: igen | F20: =IF(AND(C17=köv_valaszoljon,gazd_tev<>""),oke,IF(AND(C17=köv_valaszoljon,gazd_tev=""),valaszoljon,IF(AND(C17=ne_valaszoljon,gazd_tev<>""),torolje,oke))) -> A kitöltés megfelelő!
B22: 2. Az üzemeltető vagy tulajdonos által létrehozott termék vagy szolgáltatás - hatással van-e a tagállamok közötti kereskedelemre, ÉS - versenyez más termékekkel vagy szolgáltatásokkal a piacon? | C22: Kérjük válasszon a legördülő listában felkínált válaszok (igen/ nem) közül az alábbi útmutatás alapján. Kérjük válaszát indokolja! Az Európai Unió működéséről szóló szerződés (a továbbiakban EUMSZ) 107. cikkének (1) bekezdése kimondja: ha a Szerződések másként nem rendelkeznek, a belső piaccal összeegyeztethetetlen a tagállamok által vagy állami forrásból bármilyen formában nyújtott olyan támogatás, amely bizonyos vállalkozásoknak vagy bizonyos áruk termelésének előnyben részesítése által torzítja a versenyt, vagy azzal fenyeget, amennyiben ez érinti a tagállamok közötti kereskedelmet. Kereskedelemre gyakorolt hatás megítélése a Bizottsági közlemény alapján: Támogatási programok esetében általában elegendő megvizsgálni az adott program jellemzőit. Példa a kereskedelemre gyakorolt hatásra, hogy a támogatás a helyi kínálat fenntartása vagy növelése révén megnehezítheti a piacra lépést más tagállamok szolgáltatói számára, vagy látogatókat vonz el más tagállamok hasonló intézményeitől, programjaitól. Kevésbé kell azonban ilyen hatásra számítani, ha a gazdasági tevékenység mértéke igen csekély, amit például a rendkívül alacsony forgalom is tanúsíthat. A Bizottság számos határozatában ítélte meg úgy, hogy – tekintettel az ügyek sajátos körülményeire –, az intézkedés tisztán helyi hatással bírt és ezért nem gyakorolt hatást a tagállamok közötti kereskedelemre. Az említett ügyekben a Bizottság különösen arról bizonyosodott meg, hogy a kedvezményezett az adott tagállamon belül korlátozott területre kiterjedően értékesített termékeket, illetve nyújtott szolgáltatásokat, és más tagállamokból valószínűleg nem vonzott vevőket, továbbá, hogy az intézkedésnek előreláthatóan nem volt a marginálist meghaladó hatása a határokon átnyúló beruházások vagy letelepedés feltételeire. A külföldi látogatók aránya alapján a kereskedelemre való hatás értékelhető. Amennyiben a külföldi látogatók részaránya marginális, 1,5-2% alatti, akkor úgy tekinthető, hogy nem gyakorol hatást a kereskedelemre, így nem tartozik az állami támogatások hatálya alá. A szöveges indoklásban írja le, hogy hogyan állapította meg a külföldi vendégek részarányát. Figyelem! A kereskedelemre való hatást a fenntartási időszak végén is igazolni kell! Amennyiben a külföldi látogatószám alapján a kereskedelemre mégis hatással volt, úgy életbe lép a támogatás visszakövetelési mechanizmus. Versenyre gyakorolt hatás megítélése a Bizottsági közlemény alapján: Gyakorlati szempontból általában akkor áll fenn a Szerződés 107. cikkének (1) bekezdése szerinti versenytorzulás, amikor az állam pénzügyi előnyt biztosít egy olyan liberalizált ágazat valamely vállalkozásának, ahol verseny zajlik vagy verseny alakulhatna ki. | D22: Ha a kereskedelemre ÉS a versenyre is hatást gyakorol, akkor a kérdésre "igen" a válasz, és ekkor állami támogatásnak minősül. Ha valamelyik kérdésre nem gyakorol hatást, akkor "nem" a válasz, és ekkor nem minősül állami támogatásnak. | E22: igen | F22: =IF(áll_tám_rel=oke,IF(AND(C17=ne_valaszoljon,ker_hat<>""),torolje,IF(AND(C17=köv_valaszoljon,gazd_tev="nem",ker_hat=""),oke,IF(AND(C17=köv_valaszoljon,gazd_tev="nem",ker_hat<>""),torolje,IF(AND(C17=köv_valaszoljon,gazd_tev="igen",ker_hat=""),valaszoljon,oke)))),elozo_valasz) -> A kitöltés megfelelő!
B24: 3. Kérjük adja meg, végez-e nem állami támogatás alá eső tevékenységet (pl. közcélú tevékenységet)! | C24: Kérjük válasszon a legördülő listában felkínált válaszok (igen/ nem) közül. Válaszát indokolja! Például: fürdők esetén közcélúnak tekinthető az önkormányzattal kötött közszolgáltatási szerződés keretében végzett tevékenység. Gyógyfürdők esetén közcélú tevékenységnek tekinthető a Nemzeti Egészségbiztosítási Alapkezelővel (a továbbiakban NEAK) által finanszírozott egészségügyi szolgáltatás, a NEAK által kötött szerződés alapján. Amennyiben egyéb közcélú tevékenységet is végzett, kérjük támassza alá a közcél jelleget. Egyéb esetekben a nem gazdasági tevékenység tekinthető közcélú tevékenységnek. | D24: "Igen" válasz esetén, azaz amikor közcélú és nem közcélú tevékenységet is végez, az Állami támogatás, mind a Nem állami támogatás szabályai érvényesülnek! "Nem" válasz esetén csak az Állami támogatás szabályai érvényesek. | E24: igen | F24: =IF(F22=oke,IF(AND(C17=ne_valaszoljon,közc_tev<>""),torolje,IF(AND(C17=köv_valaszoljon,ker_hat="nem",közc_tev=""),oke,IF(AND(C17=köv_valaszoljon,ker_hat="nem",közc_tev<>""),torolje,IF(AND(C17=köv_valaszoljon,ker_hat="igen",közc_tev=""),valaszoljon,oke)))),elozo_valasz) -> A kitöltés megfelelő!
A27: Támogatható tevékenység | B27: Támogatási jogcím | C27: Jogcímhez rendelt alintézkedés | D27: PF szerinti maximális támogatási összeg | E27: PF szerinti maximális támogatási intenzitás | F27: Ellenőrzés | H27: Elrejtendő
A28: T1 | B28: Nem állami támogatás | C28: nem releváns | D28: 19675211000 | E28: 1 | F28: =IF(OR(D28="",E28=""),"",_xlfn.LET(_xlpm.ell,IF(C28=nem_rel,B28,C28),_xlpm.ell_tartomany,IF(C28=nem_rel,$B$28:$B$54,$C$28:$C$54),_xlpm.darab1,COUNTIF(_xlpm.ell_tartomany,_xlpm.ell),_xlpm.darab2,COUNTIFS(_xlpm.ell_tartomany,_xlpm.ell,$D$28:$D$54,D28,$E$28:$E$54,E28),IF(_xlpm.darab1=_xlpm.darab2,"Megfelelt","Hiba!!!"))) -> Megfelelt | H28: =IF(ISBLANK(B28),"",IF(C28=nem_rel,B28,B28&" - "&C28)) -> Nem állami támogatás | I28: =LEFT(H28,200) -> Nem állami támogatás
A29: T2 | B29: Nem állami támogatás | C29: nem releváns | D29: 19675211000 | E29: 1 | F29: =IF(OR(D29="",E29=""),"",_xlfn.LET(_xlpm.ell,IF(C29=nem_rel,B29,C29),_xlpm.ell_tartomany,IF(C29=nem_rel,$B$28:$B$54,$C$28:$C$54),_xlpm.darab1,COUNTIF(_xlpm.ell_tartomany,_xlpm.ell),_xlpm.darab2,COUNTIFS(_xlpm.ell_tartomany,_xlpm.ell,$D$28:$D$54,D29,$E$28:$E$54,E29),IF(_xlpm.darab1=_xlpm.darab2,"Megfelelt","Hiba!!!"))) -> Megfelelt | H29: =IF(ISBLANK(B29),"",IF(C29=nem_rel,B29,B29&" - "&C29)) -> Nem állami támogatás | I29: =LEFT(H29,200) -> Nem állami támogatás
A30: T3 | B30: Csekély összegű támogatás | C30: nem releváns | D30: =3000000*D79 -> 1200000000 | E30: 1 | F30: =IF(OR(D30="",E30=""),"",_xlfn.LET(_xlpm.ell,IF(C30=nem_rel,B30,C30),_xlpm.ell_tartomany,IF(C30=nem_rel,$B$28:$B$54,$C$28:$C$54),_xlpm.darab1,COUNTIF(_xlpm.ell_tartomany,_xlpm.ell),_xlpm.darab2,COUNTIFS(_xlpm.ell_tartomany,_xlpm.ell,$D$28:$D$54,D30,$E$28:$E$54,E30),IF(_xlpm.darab1=_xlpm.darab2,"Megfelelt","Hiba!!!"))) -> Megfelelt | H30: =IF(ISBLANK(B30),"",IF(C30=nem_rel,B30,B30&" - "&C30)) -> Csekély összegű támogatás | I30: =LEFT(H30,200) -> Csekély összegű támogatás
A31: T4 | B31: Környezeti károk helyreállítása | C31: az éghajlatváltozáshoz való alkalmazkodásra és annak mérséklésére szolgáló természetalapú megoldások megvalósításához nyújtott támogatás esetén | D31: 19675211000 | E31: 0.7 | F31: =IF(OR(D31="",E31=""),"",_xlfn.LET(_xlpm.ell,IF(C31=nem_rel,B31,C31),_xlpm.ell_tartomany,IF(C31=nem_rel,$B$28:$B$54,$C$28:$C$54),_xlpm.darab1,COUNTIF(_xlpm.ell_tartomany,_xlpm.ell),_xlpm.darab2,COUNTIFS(_xlpm.ell_tartomany,_xlpm.ell,$D$28:$D$54,D31,$E$28:$E$54,E31),IF(_xlpm.darab1=_xlpm.darab2,"Megfelelt","Hiba!!!"))) -> Megfelelt | H31: =IF(ISBLANK(B31),"",IF(C31=nem_rel,B31,B31&" - "&C31)) -> Környezeti károk helyreállítása - az éghajlatváltozáshoz való alkalmazkodásra és annak mérséklésére szolgáló természetalapú megoldások megvalósításához nyújtott támogatás esetén | I31: =LEFT(H31,200) -> Környezeti károk helyreállítása - az éghajlatváltozáshoz való alkalmazkodásra és annak mérséklésére szolgáló természetalapú megoldások megvalósításához nyújtott támogatás esetén
A32: T5 | B32: Környezeti károk helyreállítása | C32: a biológiai sokféleség vagy ökoszisztémák védelméhez vagy helyreállításához az ökoszisztémák jó állapotának eléréséhez való hozzájárulás vagy a már jó állapotban lévő ökoszisztémák védelme érdekében nyújtott támogatás esetén | D32: 19675211000 | E32: 0.7 | F32: =IF(OR(D32="",E32=""),"",_xlfn.LET(_xlpm.ell,IF(C32=nem_rel,B32,C32),_xlpm.ell_tartomany,IF(C32=nem_rel,$B$28:$B$54,$C$28:$C$54),_xlpm.darab1,COUNTIF(_xlpm.ell_tartomany,_xlpm.ell),_xlpm.darab2,COUNTIFS(_xlpm.ell_tartomany,_xlpm.ell,$D$28:$D$54,D32,$E$28:$E$54,E32),IF(_xlpm.darab1=_xlpm.darab2,"Megfelelt","Hiba!!!"))) -> Megfelelt | H32: =IF(ISBLANK(B32),"",IF(C32=nem_rel,B32,B32&" - "&C32)) -> Környezeti károk helyreállítása - a biológiai sokféleség vagy ökoszisztémák védelméhez vagy helyreállításához az ökoszisztémák jó állapotának eléréséhez való hozzájárulás vagy a már jó állapotban lévő ökoszisztémák védelme érdekében nyújtott támogatás esetén | I32: =LEFT(H32,200) -> Környezeti károk helyreállítása - a biológiai sokféleség vagy ökoszisztémák védelméhez vagy helyreállításához az ökoszisztémák jó állapotának eléréséhez való hozzájárulás vagy a már jó állapotban lévő
A33: T6 | B33: Regionális beruházási támogatás | C33: nem releváns | D33: 19675211000 | E33: 0.5 | F33: =IF(OR(D33="",E33=""),"",_xlfn.LET(_xlpm.ell,IF(C33=nem_rel,B33,C33),_xlpm.ell_tartomany,IF(C33=nem_rel,$B$28:$B$54,$C$28:$C$54),_xlpm.darab1,COUNTIF(_xlpm.ell_tartomany,_xlpm.ell),_xlpm.darab2,COUNTIFS(_xlpm.ell_tartomany,_xlpm.ell,$D$28:$D$54,D33,$E$28:$E$54,E33),IF(_xlpm.darab1=_xlpm.darab2,"Megfelelt","Hiba!!!"))) -> Megfelelt | H33: =IF(ISBLANK(B33),"",IF(C33=nem_rel,B33,B33&" - "&C33)) -> Regionális beruházási támogatás | I33: =LEFT(H33,200) -> Regionális beruházási támogatás
A34: T7 | B34: Megújuló energia, megújuló hidrogén és nagy hatásfokú kapcsolt energiatermeléshez nyújtott beruházási támogatás | C34: A támogatott beruházás megújulóenergia termelésre - ideértve az (EU) 2018/2001 irányelv VII. mellékletének megfelelő hőszivattyúkat -, megújuló energiaforrásokon alapuló nagy hatásfokú kapcsolt energiatermelésre és megújuló hidrogén termelésre irányul | D34: 19675211000 | E34: 1 | F34: =IF(OR(D34="",E34=""),"",_xlfn.LET(_xlpm.ell,IF(C34=nem_rel,B34,C34),_xlpm.ell_tartomany,IF(C34=nem_rel,$B$28:$B$54,$C$28:$C$54),_xlpm.darab1,COUNTIF(_xlpm.ell_tartomany,_xlpm.ell),_xlpm.darab2,COUNTIFS(_xlpm.ell_tartomany,_xlpm.ell,$D$28:$D$54,D34,$E$28:$E$54,E34),IF(_xlpm.darab1=_xlpm.darab2,"Megfelelt","Hiba!!!"))) -> Megfelelt | H34: =IF(ISBLANK(B34),"",IF(C34=nem_rel,B34,B34&" - "&C34)) -> Megújuló energia, megújuló hidrogén és nagy hatásfokú kapcsolt energiatermeléshez nyújtott beruházási támogatás - A támogatott beruházás megújulóenergia termelésre - ideértve az (EU) 2018/2001 irányelv VII. mellékletének megfelelő hőszivattyúkat -, megújuló energiaforrásokon alapuló nagy hatásfokú kapcsolt energiatermelésre és megújuló hidrogén termelésre irányul | I34: =LEFT(H34,200) -> Megújuló energia, megújuló hidrogén és nagy hatásfokú kapcsolt energiatermeléshez nyújtott beruházási támogatás - A támogatott beruházás megújulóenergia termelésre - ideértve az (EU) 2018/2001 irányel
A35: T8 | B35: Elektromos- vagy hidrogéntöltő infrastruktúrához nyújtott beruházási támogatás, csekély összegű támogatás | C35: nem releváns | D35: 19675211000 | E35: 1 | F35: Megfelelt | H35: =IF(ISBLANK(B35),"",IF(C35=nem_rel,B35,B35&" - "&C35)) -> Elektromos- vagy hidrogéntöltő infrastruktúrához nyújtott beruházási támogatás, csekély összegű támogatás | I35: =LEFT(H35,200) -> Elektromos- vagy hidrogéntöltő infrastruktúrához nyújtott beruházási támogatás, csekély összegű támogatás
A36: T9 | B36: Csekély összegű támogatás | C36: nem releváns | D36: =3000000*D79 -> 1200000000 | E36: 1 | F36: Megfelelt | H36: =IF(ISBLANK(B36),"",IF(C36=nem_rel,B36,B36&" - "&C36)) -> Csekély összegű támogatás | I36: =LEFT(H36,200) -> Csekély összegű támogatás
A37: T10 | B37: Közszolgáltatásért járó ellentételezés | C37: nem releváns | D37: 19675211000 | E37: 1 | F37: Megfelelt | H37: =IF(ISBLANK(B37),"",IF(C37=nem_rel,B37,B37&" - "&C37)) -> Közszolgáltatásért járó ellentételezés | I37: =LEFT(H37,200) -> Közszolgáltatásért járó ellentételezés
F38: =IF(OR(D38="",E38=""),"",_xlfn.LET(_xlpm.ell,IF(C38=nem_rel,B38,C38),_xlpm.ell_tartomany,IF(C38=nem_rel,$B$28:$B$54,$C$28:$C$54),_xlpm.darab1,COUNTIF(_xlpm.ell_tartomany,_xlpm.ell),_xlpm.darab2,COUNTIFS(_xlpm.ell_tartomany,_xlpm.ell,$D$28:$D$54,D38,$E$28:$E$54,E38),IF(_xlpm.darab1=_xlpm.darab2,"Megfelelt","Hiba!!!"))) | H38: =IF(ISBLANK(B38),"",IF(C38=nem_rel,B38,B38&" - "&C38)) | I38: =LEFT(H38,200)
F39: =IF(OR(D39="",E39=""),"",_xlfn.LET(_xlpm.ell,IF(C39=nem_rel,B39,C39),_xlpm.ell_tartomany,IF(C39=nem_rel,$B$28:$B$54,$C$28:$C$54),_xlpm.darab1,COUNTIF(_xlpm.ell_tartomany,_xlpm.ell),_xlpm.darab2,COUNTIFS(_xlpm.ell_tartomany,_xlpm.ell,$D$28:$D$54,D39,$E$28:$E$54,E39),IF(_xlpm.darab1=_xlpm.darab2,"Megfelelt","Hiba!!!"))) | H39: =IF(ISBLANK(B39),"",IF(C39=nem_rel,B39,B39&" - "&C39)) | I39: =LEFT(H39,200)
F40: =IF(OR(D40="",E40=""),"",_xlfn.LET(_xlpm.ell,IF(C40=nem_rel,B40,C40),_xlpm.ell_tartomany,IF(C40=nem_rel,$B$28:$B$54,$C$28:$C$54),_xlpm.darab1,COUNTIF(_xlpm.ell_tartomany,_xlpm.ell),_xlpm.darab2,COUNTIFS(_xlpm.ell_tartomany,_xlpm.ell,$D$28:$D$54,D40,$E$28:$E$54,E40),IF(_xlpm.darab1=_xlpm.darab2,"Megfelelt","Hiba!!!"))) | H40: =IF(ISBLANK(B40),"",IF(C40=nem_rel,B40,B40&" - "&C40)) | I40: =LEFT(H40,200)
F41: =IF(OR(D41="",E41=""),"",_xlfn.LET(_xlpm.ell,IF(C41=nem_rel,B41,C41),_xlpm.ell_tartomany,IF(C41=nem_rel,$B$28:$B$54,$C$28:$C$54),_xlpm.darab1,COUNTIF(_xlpm.ell_tartomany,_xlpm.ell),_xlpm.darab2,COUNTIFS(_xlpm.ell_tartomany,_xlpm.ell,$D$28:$D$54,D41,$E$28:$E$54,E41),IF(_xlpm.darab1=_xlpm.darab2,"Megfelelt","Hiba!!!"))) | H41: =IF(ISBLANK(B41),"",IF(C41=nem_rel,B41,B41&" - "&C41)) | I41: =LEFT(H41,200)
F42: =IF(OR(D42="",E42=""),"",_xlfn.LET(_xlpm.ell,IF(C42=nem_rel,B42,C42),_xlpm.ell_tartomany,IF(C42=nem_rel,$B$28:$B$54,$C$28:$C$54),_xlpm.darab1,COUNTIF(_xlpm.ell_tartomany,_xlpm.ell),_xlpm.darab2,COUNTIFS(_xlpm.ell_tartomany,_xlpm.ell,$D$28:$D$54,D42,$E$28:$E$54,E42),IF(_xlpm.darab1=_xlpm.darab2,"Megfelelt","Hiba!!!"))) | H42: =IF(ISBLANK(B42),"",IF(C42=nem_rel,B42,B42&" - "&C42)) | I42: =LEFT(H42,200)
F43: =IF(OR(D43="",E43=""),"",_xlfn.LET(_xlpm.ell,IF(C43=nem_rel,B43,C43),_xlpm.ell_tartomany,IF(C43=nem_rel,$B$28:$B$54,$C$28:$C$54),_xlpm.darab1,COUNTIF(_xlpm.ell_tartomany,_xlpm.ell),_xlpm.darab2,COUNTIFS(_xlpm.ell_tartomany,_xlpm.ell,$D$28:$D$54,D43,$E$28:$E$54,E43),IF(_xlpm.darab1=_xlpm.darab2,"Megfelelt","Hiba!!!"))) | H43: =IF(ISBLANK(B43),"",IF(C43=nem_rel,B43,B43&" - "&C43)) | I43: =LEFT(H43,200)
F44: =IF(OR(D44="",E44=""),"",_xlfn.LET(_xlpm.ell,IF(C44=nem_rel,B44,C44),_xlpm.ell_tartomany,IF(C44=nem_rel,$B$28:$B$54,$C$28:$C$54),_xlpm.darab1,COUNTIF(_xlpm.ell_tartomany,_xlpm.ell),_xlpm.darab2,COUNTIFS(_xlpm.ell_tartomany,_xlpm.ell,$D$28:$D$54,D44,$E$28:$E$54,E44),IF(_xlpm.darab1=_xlpm.darab2,"Megfelelt","Hiba!!!"))) | H44: =IF(ISBLANK(B44),"",IF(C44=nem_rel,B44,B44&" - "&C44)) | I44: =LEFT(H44,200)
F45: =IF(OR(D45="",E45=""),"",_xlfn.LET(_xlpm.ell,IF(C45=nem_rel,B45,C45),_xlpm.ell_tartomany,IF(C45=nem_rel,$B$28:$B$54,$C$28:$C$54),_xlpm.darab1,COUNTIF(_xlpm.ell_tartomany,_xlpm.ell),_xlpm.darab2,COUNTIFS(_xlpm.ell_tartomany,_xlpm.ell,$D$28:$D$54,D45,$E$28:$E$54,E45),IF(_xlpm.darab1=_xlpm.darab2,"Megfelelt","Hiba!!!"))) | H45: =IF(ISBLANK(B45),"",IF(C45=nem_rel,B45,B45&" - "&C45)) | I45: =LEFT(H45,200)
F46: =IF(OR(D46="",E46=""),"",_xlfn.LET(_xlpm.ell,IF(C46=nem_rel,B46,C46),_xlpm.ell_tartomany,IF(C46=nem_rel,$B$28:$B$54,$C$28:$C$54),_xlpm.darab1,COUNTIF(_xlpm.ell_tartomany,_xlpm.ell),_xlpm.darab2,COUNTIFS(_xlpm.ell_tartomany,_xlpm.ell,$D$28:$D$54,D46,$E$28:$E$54,E46),IF(_xlpm.darab1=_xlpm.darab2,"Megfelelt","Hiba!!!"))) | H46: =IF(ISBLANK(B46),"",IF(C46=nem_rel,B46,B46&" - "&C46)) | I46: =LEFT(H46,200)
F47: =IF(OR(D47="",E47=""),"",_xlfn.LET(_xlpm.ell,IF(C47=nem_rel,B47,C47),_xlpm.ell_tartomany,IF(C47=nem_rel,$B$28:$B$54,$C$28:$C$54),_xlpm.darab1,COUNTIF(_xlpm.ell_tartomany,_xlpm.ell),_xlpm.darab2,COUNTIFS(_xlpm.ell_tartomany,_xlpm.ell,$D$28:$D$54,D47,$E$28:$E$54,E47),IF(_xlpm.darab1=_xlpm.darab2,"Megfelelt","Hiba!!!"))) | H47: =IF(ISBLANK(B47),"",IF(C47=nem_rel,B47,B47&" - "&C47)) | I47: =LEFT(H47,200)
F48: =IF(OR(D48="",E48=""),"",_xlfn.LET(_xlpm.ell,IF(C48=nem_rel,B48,C48),_xlpm.ell_tartomany,IF(C48=nem_rel,$B$28:$B$54,$C$28:$C$54),_xlpm.darab1,COUNTIF(_xlpm.ell_tartomany,_xlpm.ell),_xlpm.darab2,COUNTIFS(_xlpm.ell_tartomany,_xlpm.ell,$D$28:$D$54,D48,$E$28:$E$54,E48),IF(_xlpm.darab1=_xlpm.darab2,"Megfelelt","Hiba!!!"))) | H48: =IF(ISBLANK(B48),"",IF(C48=nem_rel,B48,B48&" - "&C48)) | I48: =LEFT(H48,200)
F49: =IF(OR(D49="",E49=""),"",_xlfn.LET(_xlpm.ell,IF(C49=nem_rel,B49,C49),_xlpm.ell_tartomany,IF(C49=nem_rel,$B$28:$B$54,$C$28:$C$54),_xlpm.darab1,COUNTIF(_xlpm.ell_tartomany,_xlpm.ell),_xlpm.darab2,COUNTIFS(_xlpm.ell_tartomany,_xlpm.ell,$D$28:$D$54,D49,$E$28:$E$54,E49),IF(_xlpm.darab1=_xlpm.darab2,"Megfelelt","Hiba!!!"))) | H49: =IF(ISBLANK(B49),"",IF(C49=nem_rel,B49,B49&" - "&C49)) | I49: =LEFT(H49,200)
... F54: =IF(OR(D54="",E54=""),"",_xlfn.LET(_xlpm.ell,IF(C54=nem_rel,B54,C54),_xlpm.ell_tartomany,IF(C54=nem_rel,$B$28:$B$54,$C$28:$C$54),_xlpm.darab1,COUNTIF(_xlpm.ell_tartomany,_xlpm.ell),_xlpm.darab2,COUNTIFS(_xlpm.ell_tartomany,_xlpm.ell,$D$28:$D$54,D54,$E$28:$E$54,E54),IF(_xlpm.darab1=_xlpm.darab2,"Megfelelt","Hiba!!!"))) | H54: =IF(ISBLANK(B54),"",IF(C54=nem_rel,B54,B54&" - "&C54)) | I54: =LEFT(H54,200)
C58: Támogatási jogcím | D58: PF szerint igényelhető maximális támogatási összeg | E58: PF szerint igényelhető maximális támogatási intenzitás
...

Sheet Beruházási_ktg_input
E2: Kérjük töltse ki az alábbi, a beruházási költségekre vonatkozó táblázatokat:
E3: Kitöltési útmutatás: A fenti útmutatások alapján töltse ki az alábbi táblázatot. Kérjük adja meg, hogy mely beruházási elemre milyen támogatási jogcímet kíván igénybe venni a korábban megadottak alapján. A költségek meghatározásánál adja meg a fajlagos egységárat és mennyiséget, valamint az áfa kulcs mértékét. A későbbi számításokhoz jelölje be, hogy az adott költségelem elszámolható vagy nem elszámolható költség, illetve milyen költségnemhez tartozik az adott beruházási elem. Az áfa visszaigényelhetőségének szempontjából adja meg a kedvezményezett áfa státuszát is. Az egyes beruházási elemekre vonatkozó ütemezésnél adja meg, hogy az adott költség melyik évben mekkora arányban jelenik meg. Az ütemezést csak a beruházással érintett évekre kell megadni. Kérjük adja meg az egyes eszközök maradványértékét értékcsökkenés alapú számítással. Amennyiben a korábban meghatározottak szerint több támogatási szabály is releváns, kérjük ossza meg a beruházási költségeket, hogy mely állami támogatás - vagy nem állami támogatás szabály alá tartoznak. Nem állami támogatás szabály alá tartoznak azon fejlesztési elemek, amelyek a közszolgáltatással vagy a közcél ellátásával közvetlenül kapcsolatba hozhatók. (Pl. gyógyfürdők esetén a beutalóval érkező betegek ellátását jellemzően szolgálják, mint a gyógyászati közcél ellátását szolgáló medencék, kezelő helyiségek.) Állami támogatás szabály alá tartoznak azon fejlesztési elemek, amelyek csak a nem közcélú szegmens ellátását szolgálják. (Pl. gyógyfürdők esetén azon fejlesztési elemek, amelyek nem hozhatók kapcsolatba a gyógyászati céllal, mint az élménymedencék felújítása, új attrakciók létrehozása.) Azon fejlesztési elemek költségei, amelyek vegyesen a közcélú és nem közcélú szegmens ellátását szolgálják megoszthatók pl. a közcélú és nem közcélú látogatók számának arányában. (Pl. gyógyfürdők esetén a váróterem, öltözők, vizesblokkok, vendéglátóhelyiségek energetikai felújítása, valamint a támogató tevékenységek költségei, különösen a gépészeti elemek, kútfúrás, kútgépészer, csővezetékek, hőcserélők.) A költségeket kérjük pozitív előjellel mutassa be a beruházással érintett évekre!
B7: Fősor/alsor | E7: Beruházási elem | F7: Élettartam | G7: Támogatási jogcím | H7: Mértékegység | I7: Mennyiség | J7: Egységár | K7: Beruházási elem nettó ára | L7: Nettó ár | M7: Áfa kulcs | N7: Áfa összege | O7: Bruttó ár | P7: Maradványérték | Q7: Elszámolható költség / Nem elszámolható költség | R7: Költség besorolás | S7: Kedvezményezett Áfa státusza | T7: Nettó elszámolható költség | U7: Elszámolható költség Áfá-ja | V7: Összes elszámolható költség | W7: Elszámolható költség NEM visszaigényelhető Áfája. (NEM elszámolható ktg-ként) | X7: Elszámolható költség visszaigényelhető Áfája. (NEM elszámolható tétel) | Y7: Nettó NEM elszámolható költség | Z7: NEM elszámolható költség visszaigényelhető Áfája. | AA7: Nem elszámolható költség NEM visszaigényelhető Áfája | AB7: Nem elszámolható költség és annak Áfája | AC7: Összes elszámolható költség és a nem elszámolható költség nem visszaigényelhető Áfával | AD7: Összes NEM elszámolható költség | AE7: Összes költség | AF7: =start_year -> 2025 | AG7: =AF7+1 -> 2026 | AH7: =AG7+1 -> 2027 | AI7: =AH7+1 -> 2028 | AJ7: =AI7+1 -> 2029 | AK7: ütemezés ellenőrzés | AL7: ="elszámolható költségek "&AF7 -> elszámolható költségek 2025 | AM7: ="elszámolható költségek "&AG7 -> elszámolható költségek 2026 | AN7: ="elszámolható költségek "&AH7 -> elszámolható költségek 2027 | AO7: ="elszámolható költségek "&AI7 -> elszámolható költségek 2028 | AP7: ="elszámolható költségek "&AJ7 -> elszámolható költségek 2029 | AQ7: ="nem elszámolható költségek "&AF7 -> nem elszámolható költségek 2025 | AR7: ="nem elszámolható költségek "&AG7 -> nem elszámolható költségek 2026 | AS7: ="nem elszámolható költségek "&AH7 -> nem elszámolható költségek 2027 | AT7: ="nem elszámolható költségek "&AI7 -> nem elszámolható költségek 2028 | AU7: ="nem elszámolható költségek "&AJ7 -> nem elszámolható költségek 2029 | AV7: ="áfa nélküli költség "&AF7 -> áfa nélküli költség 2025 | AW7: ="áfa nélküli költség "&AG7 -> áfa nélküli költség 2026 | AX7: ="áfa nélküli költség "&AH7 -> áfa nélküli költség 2027 | AY7: ="áfa nélküli költség "&AI7 -> áfa nélküli költség 2028 | AZ7: ="áfa nélküli költség "&AJ7 -> áfa nélküli költség 2029
B8: Fősor | C8: =IF(B8=Háttér_listák!$B$121,1,0) -> 1 | D8: =IF(C8=C7,D7,D7+1) -> 1 | E8: Projekt előkészítés | G8: nem releváns | K8: =IF(B8=Háttér_listák!$B$121,"",Beruházási_ktg_input!I8*Beruházási_ktg_input!J8) | L8: =IF(B8=Háttér_listák!$B$121,SUMIF(Beruházási_ktg_input!D8:$D$107,Beruházási_ktg_input!D8+1,Beruházási_ktg_input!L8:$L$107),Beruházási_ktg_input!$K8) -> 41500000 | O8: =IF(B8=Háttér_listák!$B$121,SUMIF(Beruházási_ktg_input!$D9:D$107,Beruházási_ktg_input!D8+1,$O9:O$107),L8+N8) -> 52705000 | T8: =IF($B8=Háttér_listák!$B$121,SUMIF($D9:D$107,D8+1,$T9:T$107),IF(Q8=Háttér_listák!$B$125,Beruházási_ktg_input!L8,0)) -> 41500000 | U8: =IF($B8=Háttér_listák!$B$121,SUMIF($D9:D$107,D8+1,$U9:U$107),IF(AND(Q8=Háttér_listák!$B$125,Beruházási_ktg_input!S8=Háttér_listák!$B$130,Főoldal!$C$15="Igen"),Beruházási_ktg_input!N8,0)) -> 11205000 | V8: =SUM(T8:U8) -> 52705000 | W8: =IF($B8=Háttér_listák!$B$121,SUMIF($D9:D$107,D8+1,$W9:W$107),IF(AND(Q8=Háttér_listák!$B$125,Beruházási_ktg_input!S8=Háttér_listák!$B$130,Főoldal!$C$15="Nem"),Beruházási_ktg_input!N8,0)) -> 0 | X8: =IF($B8=Háttér_listák!$B$121,SUMIF($D9:D$107,D8+1,$X9:X$107),IF(AND(Q8=Háttér_listák!$B$125,Beruházási_ktg_input!S8=Háttér_listák!$B$129),Beruházási_ktg_input!N8,0)) -> 0 | Y8: =IF($B8=Háttér_listák!$B$121,SUMIF($D9:D$107,D8+1,$Y9:Y$107),IF(Q8=Háttér_listák!$B$126,Beruházási_ktg_input!L8,0)) -> 0 | Z8: =IF($B8=Háttér_listák!$B$121,SUMIF($D9:D$107,D8+1,$Z9:Z$107),IF(AND(Q8=Háttér_listák!$B$126,Beruházási_ktg_input!S8=Háttér_listák!$B$129),Beruházási_ktg_input!N8,0)) -> 0 | AA8: =IF($B8=Háttér_listák!$B$121,SUMIF($D9:D$107,D8+1,$AA9:AA$107),IF(AND(Q8=Háttér_listák!$B$126,Beruházási_ktg_input!S8=Háttér_listák!$B$130),Beruházási_ktg_input!N8,0)) -> 0 | AB8: =Y8+AA8 -> 0 | AC8: =V8+AB8 -> 52705000 | AD8: =SUM(W8:AA8) -> 0 | AE8: =V8+AD8 -> 52705000 | AK8: =IF(SUM(AF8:AJ8)=0,"",IF(SUM(AF8:AJ8)=1,Háttér_listák!$B$133,Háttér_listák!$B$134)) | AL8: =IF($AE8=0,0,IF($B8=Háttér_listák!$B$122,Beruházási_ktg_input!$V8*Beruházási_ktg_input!AF8,"")) | AM8: =IF($AE8=0,0,IF($B8=Háttér_listák!$B$122,Beruházási_ktg_input!$V8*Beruházási_ktg_input!AG8,"")) | AN8: =IF($AE8=0,0,IF($B8=Háttér_listák!$B$122,Beruházási_ktg_input!$V8*Beruházási_ktg_input!AH8,"")) | AO8: =IF($AE8=0,0,IF($B8=Háttér_listák!$B$122,Beruházási_ktg_input!$V8*Beruházási_ktg_input!AI8,"")) | AP8: =IF($AE8=0,0,IF($B8=Háttér_listák!$B$122,Beruházási_ktg_input!$V8*Beruházási_ktg_input!AJ8,"")) | AQ8: =IF($AE8=0,0,IF($B8=Háttér_listák!$B$122,Beruházási_ktg_input!$AD8*Beruházási_ktg_input!AF8,"")) | AR8: =IF($AE8=0,0,IF($B8=Háttér_listák!$B$122,Beruházási_ktg_input!$AD8*Beruházási_ktg_input!AG8,"")) | AS8: =IF($AE8=0,0,IF($B8=Háttér_listák!$B$122,Beruházási_ktg_input!$AD8*Beruházási_ktg_input!AH8,"")) | AT8: =IF($AE8=0,0,IF($B8=Háttér_listák!$B$122,Beruházási_ktg_input!$AD8*Beruházási_ktg_input!AI8,"")) | AU8: =IF($AE8=0,0,IF($B8=Háttér_listák!$B$122,Beruházási_ktg_input!$AD8*Beruházási_ktg_input!AJ8,"")) | AV8: =IF($AE8=0,0,IF($B8=Háttér_listák!$B$122,($T8+$Y8)*AF8,"")) | AW8: =IF($AE8=0,0,IF($B8=Háttér_listák!$B$122,($T8+$Y8)*AG8,"")) | AX8: =IF($AE8=0,0,IF($B8=Háttér_listák!$B$122,($T8+$Y8)*AH8,"")) | AY8: =IF($AE8=0,0,IF($B8=Háttér_listák!$B$122,($T8+$Y8)*AI8,"")) | AZ8: =IF($AE8=0,0,IF($B8=Háttér_listák!$B$122,($T8+$Y8)*AJ8,""))
B9: Alsor | C9: =IF(B9=Háttér_listák!$B$121,1,0) -> 0 | D9: =IF(C9=C8,D8,D8+1) -> 2 | E9: Előzetes tanulmányok, dokumentumok | F9: 0 | G9: Nem állami támogatás | I9: 1 | J9: 8000000 | K9: =IF(B9=Háttér_listák!$B$121,"",Beruházási_ktg_input!I9*Beruházási_ktg_input!J9) -> 8000000 | L9: =IF(B9=Háttér_listák!$B$121,SUMIF(Beruházási_ktg_input!D9:$D$107,Beruházási_ktg_input!D9+1,Beruházási_ktg_input!L9:$L$107),Beruházási_ktg_input!$K9) -> 8000000 | M9: 0.27 | N9: 2160000 | O9: =IF(B9=Háttér_listák!$B$121,SUMIF(Beruházási_ktg_input!$D10:D$107,Beruházási_ktg_input!D9+1,$O10:O$107),L9+N9) -> 10160000 | P9: 0 | Q9: Elszámolható költség | R9: Projektelőkészítés költségei | S9: Nem ÁFA visszaigénylő | T9: =IF($B9=Háttér_listák!$B$121,SUMIF($D10:D$107,D9+1,$T10:T$107),IF(Q9=Háttér_listák!$B$125,Beruházási_ktg_input!L9,0)) -> 8000000 | U9: =IF($B9=Háttér_listák!$B$121,SUMIF($D10:D$107,D9+1,$U10:U$107),IF(AND(Q9=Háttér_listák!$B$125,Beruházási_ktg_input!S9=Háttér_listák!$B$130,Főoldal!$C$15="Igen"),Beruházási_ktg_input!N9,0)) -> 2160000 | V9: =SUM(T9:U9) -> 10160000 | W9: =IF($B9=Háttér_listák!$B$121,SUMIF($D10:D$107,D9+1,$W10:W$107),IF(AND(Q9=Háttér_listák!$B$125,Beruházási_ktg_input!S9=Háttér_listák!$B$130,Főoldal!$C$15="Nem"),Beruházási_ktg_input!N9,0)) -> 0 | X9: =IF($B9=Háttér_listák!$B$121,SUMIF($D10:D$107,D9+1,$X10:X$107),IF(AND(Q9=Háttér_listák!$B$125,Beruházási_ktg_input!S9=Háttér_listák!$B$129),Beruházási_ktg_input!N9,0)) -> 0 | Y9: =IF($B9=Háttér_listák!$B$121,SUMIF($D10:D$107,D9+1,$Y10:Y$107),IF(Q9=Háttér_listák!$B$126,Beruházási_ktg_input!L9,0)) -> 0 | Z9: =IF($B9=Háttér_listák!$B$121,SUMIF($D10:D$107,D9+1,$Z10:Z$107),IF(AND(Q9=Háttér_listák!$B$126,Beruházási_ktg_input!S9=Háttér_listák!$B$129),Beruházási_ktg_input!N9,0)) -> 0 | AA9: =IF($B9=Háttér_listák!$B$121,SUMIF($D10:D$107,D9+1,$AA10:AA$107),IF(AND(Q9=Háttér_listák!$B$126,Beruházási_ktg_input!S9=Háttér_listák!$B$130),Beruházási_ktg_input!N9,0)) -> 0 | AB9: =Y9+AA9 -> 0 | AC9: =V9+AB9 -> 10160000 | AD9: =SUM(W9:AA9) -> 0 | AE9: =V9+AD9 -> 10160000 | AF9: 1 | AK9: =IF(SUM(AF9:AJ9)=0,"",IF(SUM(AF9:AJ9)=1,Háttér_listák!$B$133,Háttér_listák!$B$134)) -> Az ütemezés megfelelő! | AL9: =IF($AE9=0,0,IF($B9=Háttér_listák!$B$122,Beruházási_ktg_input!$V9*Beruházási_ktg_input!AF9,"")) -> 10160000 | AM9: =IF($AE9=0,0,IF($B9=Háttér_listák!$B$122,Beruházási_ktg_input!$V9*Beruházási_ktg_input!AG9,"")) -> 0 | AN9: =IF($AE9=0,0,IF($B9=Háttér_listák!$B$122,Beruházási_ktg_input!$V9*Beruházási_ktg_input!AH9,"")) -> 0 | AO9: =IF($AE9=0,0,IF($B9=Háttér_listák!$B$122,Beruházási_ktg_input!$V9*Beruházási_ktg_input!AI9,"")) -> 0 | AP9: =IF($AE9=0,0,IF($B9=Háttér_listák!$B$122,Beruházási_ktg_input!$V9*Beruházási_ktg_input!AJ9,"")) -> 0 | AQ9: =IF($AE9=0,0,IF($B9=Háttér_listák!$B$122,Beruházási_ktg_input!$AD9*Beruházási_ktg_input!AF9,"")) -> 0 | AR9: =IF($AE9=0,0,IF($B9=Háttér_listák!$B$122,Beruházási_ktg_input!$AD9*Beruházási_ktg_input!AG9,"")) -> 0 | AS9: =IF($AE9=0,0,IF($B9=Háttér_listák!$B$122,Beruházási_ktg_input!$AD9*Beruházási_ktg_input!AH9,"")) -> 0 | AT9: =IF($AE9=0,0,IF($B9=Háttér_listák!$B$122,Beruházási_ktg_input!$AD9*Beruházási_ktg_input!AI9,"")) -> 0 | AU9: =IF($AE9=0,0,IF($B9=Háttér_listák!$B$122,Beruházási_ktg_input!$AD9*Beruházási_ktg_input!AJ9,"")) -> 0 | AV9: =IF($AE9=0,0,IF($B9=Háttér_listák!$B$122,($T9+$Y9)*AF9,"")) -> 8000000 | AW9: =IF($AE9=0,0,IF($B9=Háttér_listák!$B$122,($T9+$Y9)*AG9,"")) -> 0 | AX9: =IF($AE9=0,0,IF($B9=Háttér_listák!$B$122,($T9+$Y9)*AH9,"")) -> 0 | AY9: =IF($AE9=0,0,IF($B9=Háttér_listák!$B$122,($T9+$Y9)*AI9,"")) -> 0 | AZ9: =IF($AE9=0,0,IF($B9=Háttér_listák!$B$122,($T9+$Y9)*AJ9,"")) -> 0
B10: Alsor | C10: =IF(B10=Háttér_listák!$B$121,1,0) -> 0 | D10: =IF(C10=C9,D9,D9+1) -> 2 | E10: Előzetes tanulmányok, dokumentumok | F10: 0 | G10: Nem állami támogatás | I10: 1 | J10: 13500000 | K10: =IF(B10=Háttér_listák!$B$121,"",Beruházási_ktg_input!I10*Beruházási_ktg_input!J10) -> 13500000 | L10: =IF(B10=Háttér_listák!$B$121,SUMIF(Beruházási_ktg_input!D10:$D$107,Beruházási_ktg_input!D10+1,Beruházási_ktg_input!L10:$L$107),Beruházási_ktg_input!$K10) -> 13500000 | M10: 0.27 | N10: 3645000 | O10: =IF(B10=Háttér_listák!$B$121,SUMIF(Beruházási_ktg_input!$D11:D$107,Beruházási_ktg_input!D10+1,$O11:O$107),L10+N10) -> 17145000 | P10: 0 | Q10: Elszámolható költség | R10: Projektelőkészítés költségei | S10: Nem ÁFA visszaigénylő | T10: =IF($B10=Háttér_listák!$B$121,SUMIF($D11:D$107,D10+1,$T11:T$107),IF(Q10=Háttér_listák!$B$125,Beruházási_ktg_input!L10,0)) -> 13500000 | U10: =IF($B10=Háttér_listák!$B$121,SUMIF($D11:D$107,D10+1,$U11:U$107),IF(AND(Q10=Háttér_listák!$B$125,Beruházási_ktg_input!S10=Háttér_listák!$B$130,Főoldal!$C$15="Igen"),Beruházási_ktg_input!N10,0)) -> 3645000 | V10: =SUM(T10:U10) -> 17145000 | W10: =IF($B10=Háttér_listák!$B$121,SUMIF($D11:D$107,D10+1,$W11:W$107),IF(AND(Q10=Háttér_listák!$B$125,Beruházási_ktg_input!S10=Háttér_listák!$B$130,Főoldal!$C$15="Nem"),Beruházási_ktg_input!N10,0)) -> 0 | X10: =IF($B10=Háttér_listák!$B$121,SUMIF($D11:D$107,D10+1,$X11:X$107),IF(AND(Q10=Háttér_listák!$B$125,Beruházási_ktg_input!S10=Háttér_listák!$B$129),Beruházási_ktg_input!N10,0)) -> 0 | Y10: =IF($B10=Háttér_listák!$B$121,SUMIF($D11:D$107,D10+1,$Y11:Y$107),IF(Q10=Háttér_listák!$B$126,Beruházási_ktg_input!L10,0)) -> 0 | Z10: =IF($B10=Háttér_listák!$B$121,SUMIF($D11:D$107,D10+1,$Z11:Z$107),IF(AND(Q10=Háttér_listák!$B$126,Beruházási_ktg_input!S10=Háttér_listák!$B$129),Beruházási_ktg_input!N10,0)) -> 0 | AA10: =IF($B10=Háttér_listák!$B$121,SUMIF($D11:D$107,D10+1,$AA11:AA$107),IF(AND(Q10=Háttér_listák!$B$126,Beruházási_ktg_input!S10=Háttér_listák!$B$130),Beruházási_ktg_input!N10,0)) -> 0 | AB10: =Y10+AA10 -> 0 | AC10: =V10+AB10 -> 17145000 | AD10: =SUM(W10:AA10) -> 0 | AE10: =V10+AD10 -> 17145000 | AF10: 1 | AK10: =IF(SUM(AF10:AJ10)=0,"",IF(SUM(AF10:AJ10)=1,Háttér_listák!$B$133,Háttér_listák!$B$134)) -> Az ütemezés megfelelő! | AL10: =IF($AE10=0,0,IF($B10=Háttér_listák!$B$122,Beruházási_ktg_input!$V10*Beruházási_ktg_input!AF10,"")) -> 17145000 | AM10: =IF($AE10=0,0,IF($B10=Háttér_listák!$B$122,Beruházási_ktg_input!$V10*Beruházási_ktg_input!AG10,"")) -> 0 | AN10: =IF($AE10=0,0,IF($B10=Háttér_listák!$B$122,Beruházási_ktg_input!$V10*Beruházási_ktg_input!AH10,"")) -> 0 | AO10: =IF($AE10=0,0,IF($B10=Háttér_listák!$B$122,Beruházási_ktg_input!$V10*Beruházási_ktg_input!AI10,"")) -> 0 | AP10: =IF($AE10=0,0,IF($B10=Háttér_listák!$B$122,Beruházási_ktg_input!$V10*Beruházási_ktg_input!AJ10,"")) -> 0 | AQ10: =IF($AE10=0,0,IF($B10=Háttér_listák!$B$122,Beruházási_ktg_input!$AD10*Beruházási_ktg_input!AF10,"")) -> 0 | AR10: =IF($AE10=0,0,IF($B10=Háttér_listák!$B$122,Beruházási_ktg_input!$AD10*Beruházási_ktg_input!AG10,"")) -> 0 | AS10: =IF($AE10=0,0,IF($B10=Háttér_listák!$B$122,Beruházási_ktg_input!$AD10*Beruházási_ktg_input!AH10,"")) -> 0 | AT10: =IF($AE10=0,0,IF($B10=Háttér_listák!$B$122,Beruházási_ktg_input!$AD10*Beruházási_ktg_input!AI10,"")) -> 0 | AU10: =IF($AE10=0,0,IF($B10=Háttér_listák!$B$122,Beruházási_ktg_input!$AD10*Beruházási_ktg_input!AJ10,"")) -> 0 | AV10: =IF($AE10=0,0,IF($B10=Háttér_listák!$B$122,($T10+$Y10)*AF10,"")) -> 13500000 | AW10: =IF($AE10=0,0,IF($B10=Háttér_listák!$B$122,($T10+$Y10)*AG10,"")) -> 0 | AX10: =IF($AE10=0,0,IF($B10=Háttér_listák!$B$122,($T10+$Y10)*AH10,"")) -> 0 | AY10: =IF($AE10=0,0,IF($B10=Háttér_listák!$B$122,($T10+$Y10)*AI10,"")) -> 0 | AZ10: =IF($AE10=0,0,IF($B10=Háttér_listák!$B$122,($T10+$Y10)*AJ10,"")) -> 0
B11: Alsor | C11: =IF(B11=Háttér_listák!$B$121,1,0) -> 0 | D11: =IF(C11=C10,D10,D10+1) -> 2 | E11: Műszaki dokumentáció költségei | F11: 0 | G11: Nem állami támogatás | I11: 1 | J11: 19000000 | K11: =IF(B11=Háttér_listák!$B$121,"",Beruházási_ktg_input!I11*Beruházási_ktg_input!J11) -> 19000000 | L11: =IF(B11=Háttér_listák!$B$121,SUMIF(Beruházási_ktg_input!D11:$D$107,Beruházási_ktg_input!D11+1,Beruházási_ktg_input!L11:$L$107),Beruházási_ktg_input!$K11) -> 19000000 | M11: 0.27 | N11: 5130000 | O11: =IF(B11=Háttér_listák!$B$121,SUMIF(Beruházási_ktg_input!$D12:D$107,Beruházási_ktg_input!D11+1,$O12:O$107),L11+N11) -> 24130000 | P11: 0 | Q11: Elszámolható költség | R11: Projektelőkészítés költségei | S11: Nem ÁFA visszaigénylő | T11: =IF($B11=Háttér_listák!$B$121,SUMIF($D12:D$107,D11+1,$T12:T$107),IF(Q11=Háttér_listák!$B$125,Beruházási_ktg_input!L11,0)) -> 19000000 | U11: =IF($B11=Háttér_listák!$B$121,SUMIF($D12:D$107,D11+1,$U12:U$107),IF(AND(Q11=Háttér_listák!$B$125,Beruházási_ktg_input!S11=Háttér_listák!$B$130,Főoldal!$C$15="Igen"),Beruházási_ktg_input!N11,0)) -> 5130000 | V11: =SUM(T11:U11) -> 24130000 | W11: =IF($B11=Háttér_listák!$B$121,SUMIF($D12:D$107,D11+1,$W12:W$107),IF(AND(Q11=Háttér_listák!$B$125,Beruházási_ktg_input!S11=Háttér_listák!$B$130,Főoldal!$C$15="Nem"),Beruházási_ktg_input!N11,0)) -> 0 | X11: =IF($B11=Háttér_listák!$B$121,SUMIF($D12:D$107,D11+1,$X12:X$107),IF(AND(Q11=Háttér_listák!$B$125,Beruházási_ktg_input!S11=Háttér_listák!$B$129),Beruházási_ktg_input!N11,0)) -> 0 | Y11: =IF($B11=Háttér_listák!$B$121,SUMIF($D12:D$107,D11+1,$Y12:Y$107),IF(Q11=Háttér_listák!$B$126,Beruházási_ktg_input!L11,0)) -> 0 | Z11: =IF($B11=Háttér_listák!$B$121,SUMIF($D12:D$107,D11+1,$Z12:Z$107),IF(AND(Q11=Háttér_listák!$B$126,Beruházási_ktg_input!S11=Háttér_listák!$B$129),Beruházási_ktg_input!N11,0)) -> 0 | AA11: =IF($B11=Háttér_listák!$B$121,SUMIF($D12:D$107,D11+1,$AA12:AA$107),IF(AND(Q11=Háttér_listák!$B$126,Beruházási_ktg_input!S11=Háttér_listák!$B$130),Beruházási_ktg_input!N11,0)) -> 0 | AB11: =Y11+AA11 -> 0 | AC11: =V11+AB11 -> 24130000 | AD11: =SUM(W11:AA11) -> 0 | AE11: =V11+AD11 -> 24130000 | AF11: 1 | AK11: =IF(SUM(AF11:AJ11)=0,"",IF(SUM(AF11:AJ11)=1,Háttér_listák!$B$133,Háttér_listák!$B$134)) -> Az ütemezés megfelelő! | AL11: =IF($AE11=0,0,IF($B11=Háttér_listák!$B$122,Beruházási_ktg_input!$V11*Beruházási_ktg_input!AF11,"")) -> 24130000 | AM11: =IF($AE11=0,0,IF($B11=Háttér_listák!$B$122,Beruházási_ktg_input!$V11*Beruházási_ktg_input!AG11,"")) -> 0 | AN11: =IF($AE11=0,0,IF($B11=Háttér_listák!$B$122,Beruházási_ktg_input!$V11*Beruházási_ktg_input!AH11,"")) -> 0 | AO11: =IF($AE11=0,0,IF($B11=Háttér_listák!$B$122,Beruházási_ktg_input!$V11*Beruházási_ktg_input!AI11,"")) -> 0 | AP11: =IF($AE11=0,0,IF($B11=Háttér_listák!$B$122,Beruházási_ktg_input!$V11*Beruházási_ktg_input!AJ11,"")) -> 0 | AQ11: =IF($AE11=0,0,IF($B11=Háttér_listák!$B$122,Beruházási_ktg_input!$AD11*Beruházási_ktg_input!AF11,"")) -> 0 | AR11: =IF($AE11=0,0,IF($B11=Háttér_listák!$B$122,Beruházási_ktg_input!$AD11*Beruházási_ktg_input!AG11,"")) -> 0 | AS11: =IF($AE11=0,0,IF($B11=Háttér_listák!$B$122,Beruházási_ktg_input!$AD11*Beruházási_ktg_input!AH11,"")) -> 0 | AT11: =IF($AE11=0,0,IF($B11=Háttér_listák!$B$122,Beruházási_ktg_input!$AD11*Beruházási_ktg_input!AI11,"")) -> 0 | AU11: =IF($AE11=0,0,IF($B11=Háttér_listák!$B$122,Beruházási_ktg_input!$AD11*Beruházási_ktg_input!AJ11,"")) -> 0 | AV11: =IF($AE11=0,0,IF($B11=Háttér_listák!$B$122,($T11+$Y11)*AF11,"")) -> 19000000 | AW11: =IF($AE11=0,0,IF($B11=Háttér_listák!$B$122,($T11+$Y11)*AG11,"")) -> 0 | AX11: =IF($AE11=0,0,IF($B11=Háttér_listák!$B$122,($T11+$Y11)*AH11,"")) -> 0 | AY11: =IF($AE11=0,0,IF($B11=Háttér_listák!$B$122,($T11+$Y11)*AI11,"")) -> 0 | AZ11: =IF($AE11=0,0,IF($B11=Háttér_listák!$B$122,($T11+$Y11)*AJ11,"")) -> 0
B12: Alsor | C12: =IF(B12=Háttér_listák!$B$121,1,0) -> 0 | D12: =IF(C12=C11,D11,D11+1) -> 2 | E12: Közbeszerzés költsége | F12: 0 | G12: Nem állami támogatás | I12: 1 | J12: 500000 | K12: =IF(B12=Háttér_listák!$B$121,"",Beruházási_ktg_input!I12*Beruházási_ktg_input!J12) -> 500000 | L12: =IF(B12=Háttér_listák!$B$121,SUMIF(Beruházási_ktg_input!D12:$D$107,Beruházási_ktg_input!D12+1,Beruházási_ktg_input!L12:$L$107),Beruházási_ktg_input!$K12) -> 500000 | M12: 0.27 | N12: 135000 | O12: =IF(B12=Háttér_listák!$B$121,SUMIF(Beruházási_ktg_input!$D13:D$107,Beruházási_ktg_input!D12+1,$O13:O$107),L12+N12) -> 635000 | P12: 0 | Q12: Elszámolható költség | R12: Projektelőkészítés költségei | S12: Nem ÁFA visszaigénylő | T12: =IF($B12=Háttér_listák!$B$121,SUMIF($D13:D$107,D12+1,$T13:T$107),IF(Q12=Háttér_listák!$B$125,Beruházási_ktg_input!L12,0)) -> 500000 | U12: =IF($B12=Háttér_listák!$B$121,SUMIF($D13:D$107,D12+1,$U13:U$107),IF(AND(Q12=Háttér_listák!$B$125,Beruházási_ktg_input!S12=Háttér_listák!$B$130,Főoldal!$C$15="Igen"),Beruházási_ktg_input!N12,0)) -> 135000 | V12: =SUM(T12:U12) -> 635000 | W12: =IF($B12=Háttér_listák!$B$121,SUMIF($D13:D$107,D12+1,$W13:W$107),IF(AND(Q12=Háttér_listák!$B$125,Beruházási_ktg_input!S12=Háttér_listák!$B$130,Főoldal!$C$15="Nem"),Beruházási_ktg_input!N12,0)) -> 0 | X12: =IF($B12=Háttér_listák!$B$121,SUMIF($D13:D$107,D12+1,$X13:X$107),IF(AND(Q12=Háttér_listák!$B$125,Beruházási_ktg_input!S12=Háttér_listák!$B$129),Beruházási_ktg_input!N12,0)) -> 0 | Y12: =IF($B12=Háttér_listák!$B$121,SUMIF($D13:D$107,D12+1,$Y13:Y$107),IF(Q12=Háttér_listák!$B$126,Beruházási_ktg_input!L12,0)) -> 0 | Z12: =IF($B12=Háttér_listák!$B$121,SUMIF($D13:D$107,D12+1,$Z13:Z$107),IF(AND(Q12=Háttér_listák!$B$126,Beruházási_ktg_input!S12=Háttér_listák!$B$129),Beruházási_ktg_input!N12,0)) -> 0 | AA12: =IF($B12=Háttér_listák!$B$121,SUMIF($D13:D$107,D12+1,$AA13:AA$107),IF(AND(Q12=Háttér_listák!$B$126,Beruházási_ktg_input!S12=Háttér_listák!$B$130),Beruházási_ktg_input!N12,0)) -> 0 | AB12: =Y12+AA12 -> 0 | AC12: =V12+AB12 -> 635000 | AD12: =SUM(W12:AA12) -> 0 | AE12: =V12+AD12 -> 635000 | AF12: 1 | AK12: =IF(SUM(AF12:AJ12)=0,"",IF(SUM(AF12:AJ12)=1,Háttér_listák!$B$133,Háttér_listák!$B$134)) -> Az ütemezés megfelelő! | AL12: =IF($AE12=0,0,IF($B12=Háttér_listák!$B$122,Beruházási_ktg_input!$V12*Beruházási_ktg_input!AF12,"")) -> 635000 | AM12: =IF($AE12=0,0,IF($B12=Háttér_listák!$B$122,Beruházási_ktg_input!$V12*Beruházási_ktg_input!AG12,"")) -> 0 | AN12: =IF($AE12=0,0,IF($B12=Háttér_listák!$B$122,Beruházási_ktg_input!$V12*Beruházási_ktg_input!AH12,"")) -> 0 | AO12: =IF($AE12=0,0,IF($B12=Háttér_listák!$B$122,Beruházási_ktg_input!$V12*Beruházási_ktg_input!AI12,"")) -> 0 | AP12: =IF($AE12=0,0,IF($B12=Háttér_listák!$B$122,Beruházási_ktg_input!$V12*Beruházási_ktg_input!AJ12,"")) -> 0 | AQ12: =IF($AE12=0,0,IF($B12=Háttér_listák!$B$122,Beruházási_ktg_input!$AD12*Beruházási_ktg_input!AF12,"")) -> 0 | AR12: =IF($AE12=0,0,IF($B12=Háttér_listák!$B$122,Beruházási_ktg_input!$AD12*Beruházási_ktg_input!AG12,"")) -> 0 | AS12: =IF($AE12=0,0,IF($B12=Háttér_listák!$B$122,Beruházási_ktg_input!$AD12*Beruházási_ktg_input!AH12,"")) -> 0 | AT12: =IF($AE12=0,0,IF($B12=Háttér_listák!$B$122,Beruházási_ktg_input!$AD12*Beruházási_ktg_input!AI12,"")) -> 0 | AU12: =IF($AE12=0,0,IF($B12=Háttér_listák!$B$122,Beruházási_ktg_input!$AD12*Beruházási_ktg_input!AJ12,"")) -> 0 | AV12: =IF($AE12=0,0,IF($B12=Háttér_listák!$B$122,($T12+$Y12)*AF12,"")) -> 500000 | AW12: =IF($AE12=0,0,IF($B12=Háttér_listák!$B$122,($T12+$Y12)*AG12,"")) -> 0 | AX12: =IF($AE12=0,0,IF($B12=Háttér_listák!$B$122,($T12+$Y12)*AH12,"")) -> 0 | AY12: =IF($AE12=0,0,IF($B12=Háttér_listák!$B$122,($T12+$Y12)*AI12,"")) -> 0 | AZ12: =IF($AE12=0,0,IF($B12=Háttér_listák!$B$122,($T12+$Y12)*AJ12,"")) -> 0
